<?xml version="1.0" encoding="utf-8"?>
<!-- This URDF was automatically created by SolidWorks to URDF Exporter! Originally created by Stephen Brawner (brawner@gmail.com) 
     Commit Version: 1.6.0-4-g7f85cfe  Build Version: 1.6.7995.38578
     For more information, please see http://wiki.ros.org/sw_urdf_exporter -->
<robot
  name="reddogv2">
  <link
    name="base">
    <inertial>
      <origin
        xyz="-0.00049526 -0.00246477 0.00397262"
        rpy="0 0 0" />
      <mass
        value="2.38753000" />
      <inertia
        ixx="0.00657139"
        ixy="-0.00000182"
        ixz="-0.00001915"
        iyy="0.02056086"
        iyz="-0.00000315"
        izz="0.02489182" />
    </inertial>
    <visual>
      <origin
        xyz="0 0 0"
        rpy="0 0 0" />
      <geometry>
        <mesh
          filename="../meshes/base_link.STL" />
      </geometry>
      <material
        name="">
        <color
          rgba="0.752941176470588 0.752941176470588 0.752941176470588 1" />
      </material>
    </visual>
    <collision>
      <origin
        xyz="0 0 0"
        rpy="0 0 0" />
      <geometry>
        <mesh
          filename="../meshes/base_link.STL" />
      </geometry>
    </collision>
  </link>
  <link
    name="FL_hip">
    <inertial>
      <origin
        xyz="0.03749935 0.01393191 -0.00000145"
        rpy="0 0 0" />
      <mass
        value="0.32473000" />
      <inertia
        ixx="0.00012292"
        ixy="0.00000496"
        ixz="0.00000008"
        iyy="0.00013972"
        iyz="0.000000001"
        izz="0.00013011" />
    </inertial>
    <visual>
      <origin
        xyz="0 0 0"
        rpy="0 0 0" />
      <geometry>
        <mesh
          filename="../meshes/FL_hip.STL" />
      </geometry>
      <material
        name="">
        <color
          rgba="0.752941176470588 0.752941176470588 0.752941176470588 1" />
      </material>
    </visual>
    <collision>
      <origin
        xyz="0 0 0"
        rpy="0 0 0" />
      <geometry>
        <mesh
          filename="../meshes/FL_hip.STL" />
      </geometry>
    </collision>
  </link>
  <joint
    name="FL_hip_joint"
    type="revolute">
    <origin
      xyz="0.127849975000003 0.052569696969697 0"
      rpy="0 0 0" />
    <parent
      link="base" />
    <child
      link="FL_hip" />
    <axis
      xyz="1 0 0" />
    <limit
      lower="-9.42"
      upper="9.42"
      effort="23.7"
      velocity="30.1" />
  </joint>
  <link
    name="FL_thigh">
    <inertial>
      <origin
        xyz="-0.00008536 0.02535762 -0.12011923"
        rpy="0 0 0" />
      <mass
        value="0.36170000" />
      <inertia
        ixx="0.00046343"
        ixy="0.00000052"
        ixz="0.00000051"
        iyy="0.00046925"
        iyz="-0.00006450"
        izz="0.00014597" />
    </inertial>
    <visual>
      <origin
        xyz="0 0 0"
        rpy="0 0 0" />
      <geometry>
        <mesh
          filename="../meshes/FL_thigh.STL" />
      </geometry>
      <material
        name="">
        <color
          rgba="0.752941176470588 0.752941176470588 0.752941176470588 1" />
      </material>
    </visual>
    <collision>
      <origin
        xyz="0 0 0"
        rpy="0 0 0" />
      <geometry>
        <mesh
          filename="../meshes/FL_thigh.STL" />
      </geometry>
    </collision>
  </link>
  <joint
    name="FL_thigh_joint"
    type="revolute">
    <origin
      xyz="0.038500025 0.0374999999999999 0"
      rpy="0 0 0" />
    <parent
      link="FL_hip" />
    <child
      link="FL_thigh" />
    <axis
      xyz="0 1 0" />
    <limit
      lower="-9.42"
      upper="9.42"
      effort="23.7"
      velocity="30.1" />
  </joint>
  <link
    name="FL_calf">
    <inertial>
      <origin
        xyz="-0.01342846 0.01083610 -0.03583329"
        rpy="0 0 0" />
      <mass
        value="0.07020000" />
      <inertia
        ixx="0.00014252"
        ixy="0.00000121"
        ixz="0.00000337"
        iyy="0.00016911"
        iyz="0.00000626"
        izz="0.00003162" />
    </inertial>
    <visual>
      <origin
        xyz="0 0 0"
        rpy="0 0 0" />
      <geometry>
        <mesh
          filename="../meshes/FL_calf.STL" />
      </geometry>
      <material
        name="">
        <color
          rgba="0.286274509803922 0.286274509803922 0.286274509803922 1" />
      </material>
    </visual>
    <collision>
      <origin
        xyz="0 0 0"
        rpy="0 0 0" />
      <geometry>
        <mesh
          filename="../meshes/FL_calf.STL" />
      </geometry>
    </collision>
  </link>
  <joint
    name="FL_calf_joint"
    type="revolute">
    <origin
      xyz="0 0.0357602928805075 -0.129999999999999"
      rpy="0 0 0" />
    <parent
      link="FL_thigh" />
    <child
      link="FL_calf" />
    <axis
      xyz="0 1 0" />
    <limit
      lower="-9.42"
      upper="9.42"
      effort="35.55"
      velocity="20.07" />
  </joint>
  <link
    name="FL_foot">
    <inertial>
      <origin
        xyz="0.00036681 -0.00004956 0.01459165"
        rpy="0 0 0" />
      <mass
        value="0.01019000" />
      <inertia
        ixx="0.00000105"
        ixy="0.000000001"
        ixz="0.00000004"
        iyy="0.00000106"
        iyz="0.000000001"
        izz="0.00000118" />
    </inertial>
    <visual>
      <origin
        xyz="0 0 0"
        rpy="0 0 0" />
      <geometry>
        <mesh
          filename="../meshes/FL_foot.STL" />
      </geometry>
      <material
        name="">
        <color
          rgba="0.752941176470588 0.752941176470588 0.752941176470588 1" />
      </material>
    </visual>
    <collision>
      <origin
        xyz="0 0 0"
        rpy="0 0 0" />
      <geometry>
        <mesh
          filename="../meshes/FL_foot.STL" />
      </geometry>
    </collision>
  </link>
  <joint
    name="FL_foot_joint"
    type="fixed" dont_collapse="true">
    <origin
      xyz="-0.000126383026934546 0.00527026536374897 -0.156"
      rpy="0 0 0" />
    <parent
      link="FL_calf" />
    <child
      link="FL_foot" />
    <axis
      xyz="0 0 0" />
  </joint>
  <link
    name="FR_hip">
    <inertial>
      <origin
        xyz="0.03749932 -0.01393189 -0.00000147"
        rpy="0 0 0" />
      <mass
        value="0.32473000" />
      <inertia
        ixx="0.00012292"
        ixy="-0.00000496"
        ixz="0.00000008"
        iyy="0.00013972"
        iyz="0.000000001"
        izz="0.00013012" />
    </inertial>
    <visual>
      <origin
        xyz="0 0 0"
        rpy="0 0 0" />
      <geometry>
        <mesh
          filename="../meshes/FR_hip.STL" />
      </geometry>
      <material
        name="">
        <color
          rgba="0.752941176470588 0.752941176470588 0.752941176470588 1" />
      </material>
    </visual>
    <collision>
      <origin
        xyz="0 0 0"
        rpy="0 0 0" />
      <geometry>
        <mesh
          filename="../meshes/FR_hip.STL" />
      </geometry>
    </collision>
  </link>
  <joint
    name="FR_hip_joint"
    type="revolute">
    <origin
      xyz="0.127849975000003 -0.057430303030303 0"
      rpy="0 0 0" />
    <parent
      link="base" />
    <child
      link="FR_hip" />
    <axis
      xyz="1 0 0" />
    <limit
      lower="-9.42"
      upper="9.42"
      effort="23.7"
      velocity="30.1" />
  </joint>
  <link
    name="FR_thigh">
    <inertial>
      <origin
        xyz="-0.00008544 -0.02535764 -0.12012032"
        rpy="0 0 0" />
      <mass
        value="0.36170000" />
      <inertia
        ixx="0.00046340"
        ixy="-0.00000052"
        ixz="0.00000051"
        iyy="0.00046922"
        iyz="0.00006450"
        izz="0.00014598" />
    </inertial>
    <visual>
      <origin
        xyz="0 0 0"
        rpy="0 0 0" />
      <geometry>
        <mesh
          filename="../meshes/FR_thigh.STL" />
      </geometry>
      <material
        name="">
        <color
          rgba="0.752941176470588 0.752941176470588 0.752941176470588 1" />
      </material>
    </visual>
    <collision>
      <origin
        xyz="0 0 0"
        rpy="0 0 0" />
      <geometry>
        <mesh
          filename="../meshes/FR_thigh.STL" />
      </geometry>
    </collision>
  </link>
  <joint
    name="FR_thigh_joint"
    type="revolute">
    <origin
      xyz="0.0385000250000001 -0.0374999999999998 0"
      rpy="0 0 0" />
    <parent
      link="FR_hip" />
    <child
      link="FR_thigh" />
    <axis
      xyz="0 1 0" />
    <limit
      lower="-9.42"
      upper="9.42"
      effort="23.7"
      velocity="30.1" />
  </joint>
  <link
    name="FR_calf">
    <inertial>
      <origin
        xyz="-0.01342849 -0.01083621 -0.03583166"
        rpy="0 0 0" />
      <mass
        value="0.07020000" />
      <inertia
        ixx="0.00014253"
        ixy="-0.00000121"
        ixz="0.00000337"
        iyy="0.00016913"
        iyz="-0.00000626"
        izz="0.00003162" />
    </inertial>
    <visual>
      <origin
        xyz="0 0 0"
        rpy="0 0 0" />
      <geometry>
        <mesh
          filename="../meshes/FR_calf.STL" />
      </geometry>
      <material
        name="">
        <color
          rgba="0.286274509803922 0.286274509803922 0.286274509803922 1" />
      </material>
    </visual>
    <collision>
      <origin
        xyz="0 0 0"
        rpy="0 0 0" />
      <geometry>
        <mesh
          filename="../meshes/FR_calf.STL" />
      </geometry>
    </collision>
  </link>
  <joint
    name="FR_calf_joint"
    type="revolute">
    <origin
      xyz="0 -0.0357602928805074 -0.129999999999999"
      rpy="0 0 0" />
    <parent
      link="FR_thigh" />
    <child
      link="FR_calf" />
    <axis
      xyz="0 1 0" />
    <limit
      lower="-9.42"
      upper="9.42"
      effort="35.55"
      velocity="20.07" />
  </joint>
  <link
    name="FR_foot">
    <inertial>
      <origin
        xyz="0.00036670 0.00004956 0.01459176"
        rpy="0 0 0" />
      <mass
        value="0.01019000" />
      <inertia
        ixx="0.00000104"
        ixy="0.000000001"
        ixz="0.00000004"
        iyy="0.00000106"
        iyz="0.000000001"
        izz="0.00000118" />
    </inertial>
    <visual>
      <origin
        xyz="0 0 0"
        rpy="0 0 0" />
      <geometry>
        <mesh
          filename="../meshes/FR_foot.STL" />
      </geometry>
      <material
        name="">
        <color
          rgba="0.752941176470588 0.752941176470588 0.752941176470588 1" />
      </material>
    </visual>
    <collision>
      <origin
        xyz="0 0 0"
        rpy="0 0 0" />
      <geometry>
        <mesh
          filename="../meshes/FR_foot.STL" />
      </geometry>
    </collision>
  </link>
  <joint
    name="FR_foot_joint"
    type="fixed" dont_collapse="true">
    <origin
      xyz="-0.000126383026935517 -0.00527026536374889 -0.156"
      rpy="0 0 0" />
    <parent
      link="FR_calf" />
    <child
      link="FR_foot" />
    <axis
      xyz="0 0 0" />
  </joint>
  <link
    name="RL_hip">
    <inertial>
      <origin
        xyz="-0.03749935 0.01393191 0.00000145"
        rpy="0 0 0" />
      <mass
        value="0.32473000" />
      <inertia
        ixx="0.00012292"
        ixy="-0.00000496"
        ixz="0.00000008"
        iyy="0.00013972"
        iyz="0.000000001"
        izz="0.00013011" />
    </inertial>
    <visual>
      <origin
        xyz="0 0 0"
        rpy="0 0 0" />
      <geometry>
        <mesh
          filename="../meshes/RL_hip.STL" />
      </geometry>
      <material
        name="">
        <color
          rgba="0.752941176470588 0.752941176470588 0.752941176470588 1" />
      </material>
    </visual>
    <collision>
      <origin
        xyz="0 0 0"
        rpy="0 0 0" />
      <geometry>
        <mesh
          filename="../meshes/RL_hip.STL" />
      </geometry>
    </collision>
  </link>
  <joint
    name="RL_hip_joint"
    type="revolute">
    <origin
      xyz="-0.128149974999993 0.052569696969696 0"
      rpy="0 0 0" />
    <parent
      link="base" />
    <child
      link="RL_hip" />
    <axis
      xyz="1 0 0" />
    <limit
      lower="-9.42"
      upper="9.42"
      effort="23.7"
      velocity="30.1" />
  </joint>
  <link
    name="RL_thigh">
    <inertial>
      <origin
        xyz="-0.00008536 0.02535762 -0.12011923"
        rpy="0 0 0" />
      <mass
        value="0.36170000" />
      <inertia
        ixx="0.00046343"
        ixy="0.00000052"
        ixz="0.00000051"
        iyy="0.00046925"
        iyz="-0.00006450"
        izz="0.00014597" />
    </inertial>
    <visual>
      <origin
        xyz="0 0 0"
        rpy="0 0 0" />
      <geometry>
        <mesh
          filename="../meshes/RL_thigh.STL" />
      </geometry>
      <material
        name="">
        <color
          rgba="0.752941176470588 0.752941176470588 0.752941176470588 1" />
      </material>
    </visual>
    <collision>
      <origin
        xyz="0 0 0"
        rpy="0 0 0" />
      <geometry>
        <mesh
          filename="../meshes/RL_thigh.STL" />
      </geometry>
    </collision>
  </link>
  <joint
    name="RL_thigh_joint"
    type="revolute">
    <origin
      xyz="-0.0385000250000009 0.0374999999999898 0"
      rpy="0 0 0" />
    <parent
      link="RL_hip" />
    <child
      link="RL_thigh" />
    <axis
      xyz="0 1 0" />
    <limit
      lower="-9.42"
      upper="9.42"
      effort="23.7"
      velocity="30.1" />
  </joint>
  <link
    name="RL_calf">
    <inertial>
      <origin
        xyz="0.01342808 0.01083611 -0.03583229"
        rpy="0 0 0" />
      <mass
        value="0.07020000" />
      <inertia
        ixx="0.00014252"
        ixy="-0.00000121"
        ixz="-0.00000337"
        iyy="0.00016912"
        iyz="0.00000626"
        izz="0.00003161" />
    </inertial>
    <visual>
      <origin
        xyz="0 0 0"
        rpy="0 0 0" />
      <geometry>
        <mesh
          filename="../meshes/RL_calf.STL" />
      </geometry>
      <material
        name="">
        <color
          rgba="0.286274509803922 0.286274509803922 0.286274509803922 1" />
      </material>
    </visual>
    <collision>
      <origin
        xyz="0 0 0"
        rpy="0 0 0" />
      <geometry>
        <mesh
          filename="../meshes/RL_calf.STL" />
      </geometry>
    </collision>
  </link>
  <joint
    name="RL_calf_joint"
    type="revolute">
    <origin
      xyz="0 0.0357602928805211 -0.130000000000007"
      rpy="0 0 0" />
    <parent
      link="RL_thigh" />
    <child
      link="RL_calf" />
    <axis
      xyz="0 1 0" />
    <limit
      lower="-9.42"
      upper="9.42"
      effort="35.55"
      velocity="20.07" />
  </joint>
  <link
    name="RL_foot">
    <inertial>
      <origin
        xyz="-0.00038651 -0.00004956 0.01459693"
        rpy="0 0 0" />
      <mass
        value="0.01019000" />
      <inertia
        ixx="0.00000105"
        ixy="0.000000001"
        ixz="-0.00000004"
        iyy="0.00000106"
        iyz="0.000000001"
        izz="0.00000118" />
    </inertial>
    <visual>
      <origin
        xyz="0 0 0"
        rpy="0 0 0" />
      <geometry>
        <mesh
          filename="../meshes/RL_foot.STL" />
      </geometry>
      <material
        name="">
        <color
          rgba="0.752941176470588 0.752941176470588 0.752941176470588 1" />
      </material>
    </visual>
    <collision>
      <origin
        xyz="0 0 0"
        rpy="0 0 0" />
      <geometry>
        <mesh
          filename="../meshes/RL_foot.STL" />
      </geometry>
    </collision>
  </link>
  <joint
    name="RL_foot_joint"
    type="fixed" dont_collapse="true">
    <origin
      xyz="0.000126383026936377 0.00527026536374187 -0.155999999999993"
      rpy="0 0 0" />
    <parent
      link="RL_calf" />
    <child
      link="RL_foot" />
    <axis
      xyz="0 0 0" />
  </joint>
  <link
    name="RR_hip">
    <inertial>
      <origin
        xyz="-0.03749932 -0.01393189 0.00000146"
        rpy="0 0 0" />
      <mass
        value="0.32473000" />
      <inertia
        ixx="0.00012292"
        ixy="0.00000496"
        ixz="0.00000008"
        iyy="0.00013972"
        iyz="0.000000001"
        izz="0.00013011" />
    </inertial>
    <visual>
      <origin
        xyz="0 0 0"
        rpy="0 0 0" />
      <geometry>
        <mesh
          filename="../meshes/RR_hip.STL" />
      </geometry>
      <material
        name="">
        <color
          rgba="0.752941176470588 0.752941176470588 0.752941176470588 1" />
      </material>
    </visual>
    <collision>
      <origin
        xyz="0 0 0"
        rpy="0 0 0" />
      <geometry>
        <mesh
          filename="../meshes/RR_hip.STL" />
      </geometry>
    </collision>
  </link>
  <joint
    name="RR_hip_joint"
    type="revolute">
    <origin
      xyz="-0.128149974999996 -0.057430303030302 0"
      rpy="0 0 0" />
    <parent
      link="base" />
    <child
      link="RR_hip" />
    <axis
      xyz="1 0 0" />
    <limit
      lower="-9.42"
      upper="9.42"
      effort="23.7"
      velocity="30.1" />
  </joint>
  <link
    name="RR_thigh">
    <inertial>
      <origin
        xyz="-0.00008543 -0.02535764 -0.12012031"
        rpy="0 0 0" />
      <mass
        value="0.36170000" />
      <inertia
        ixx="0.00046340"
        ixy="-0.00000052"
        ixz="0.00000051"
        iyy="0.00046922"
        iyz="0.00006450"
        izz="0.00014598" />
    </inertial>
    <visual>
      <origin
        xyz="0 0 0"
        rpy="0 0 0" />
      <geometry>
        <mesh
          filename="../meshes/RR_thigh.STL" />
      </geometry>
      <material
        name="">
        <color
          rgba="0.752941176470588 0.752941176470588 0.752941176470588 1" />
      </material>
    </visual>
    <collision>
      <origin
        xyz="0 0 0"
        rpy="0 0 0" />
      <geometry>
        <mesh
          filename="../meshes/RR_thigh.STL" />
      </geometry>
    </collision>
  </link>
  <joint
    name="RR_thigh_joint"
    type="revolute">
    <origin
      xyz="-0.0385000250000022 -0.0374999999999918 0"
      rpy="0 0 0" />
    <parent
      link="RR_hip" />
    <child
      link="RR_thigh" />
    <axis
      xyz="0 1 0" />
    <limit
      lower="-9.42"
      upper="9.42"
      effort="23.7"
      velocity="30.1" />
  </joint>
  <link
    name="RR_calf">
    <inertial>
      <origin
        xyz="0.01342880 -0.01083622 -0.03583285"
        rpy="0 0 0" />
      <mass
        value="0.07020000" />
      <inertia
        ixx="0.00014253"
        ixy="0.00000121"
        ixz="-0.00000337"
        iyy="0.00016913"
        iyz="-0.00000626"
        izz="0.00003162" />
    </inertial>
    <visual>
      <origin
        xyz="0 0 0"
        rpy="0 0 0" />
      <geometry>
        <mesh
          filename="../meshes/RR_calf.STL" />
      </geometry>
      <material
        name="">
        <color
          rgba="0.286274509803922 0.286274509803922 0.286274509803922 1" />
      </material>
    </visual>
    <collision>
      <origin
        xyz="0 0 0"
        rpy="0 0 0" />
      <geometry>
        <mesh
          filename="../meshes/RR_calf.STL" />
      </geometry>
    </collision>
  </link>
  <joint
    name="RR_calf_joint"
    type="revolute">
    <origin
      xyz="0 -0.0357602928805216 -0.130000000000004"
      rpy="0 0 0" />
    <parent
      link="RR_thigh" />
    <child
      link="RR_calf" />
    <axis
      xyz="0 1 0" />
    <limit
      lower="-9.42"
      upper="9.42"
      effort="35.55"
      velocity="20.07" />
  </joint>
  <link
    name="RR_foot">
    <inertial>
      <origin
        xyz="-0.00038655 0.00004956 0.01459708"
        rpy="0 0 0" />
      <mass
        value="0.01019000" />
      <inertia
        ixx="0.00000105"
        ixy="0.000000001"
        ixz="-0.00000004"
        iyy="0.00000106"
        iyz="0.000000001"
        izz="0.00000118" />
    </inertial>
    <visual>
      <origin
        xyz="0 0 0"
        rpy="0 0 0" />
      <geometry>
        <mesh
          filename="../meshes/RR_foot.STL" />
      </geometry>
      <material
        name="">
        <color
          rgba="0.752941176470588 0.752941176470588 0.752941176470588 1" />
      </material>
    </visual>
    <collision>
      <origin
        xyz="0 0 0"
        rpy="0 0 0" />
      <geometry>
        <mesh
          filename="../meshes/RR_foot.STL" />
      </geometry>
    </collision>
  </link>
  <joint
    name="RR_foot_joint"
    type="fixed" dont_collapse="true">
    <origin
      xyz="0.00012638 -0.0052703 -0.156"
      rpy="0 0 0" />
    <parent
      link="RR_calf" />
    <child
      link="RR_foot" />
    <axis
      xyz="0 0 0" />
  </joint>
</robot>